Workbook

Sheet Revenue Dashboard
A1: SINHA'S GmbH — Revenue & Occupancy Dashboard
B3: PORTFOLIO KPIs | F3: REVENUE KPIs (CHF)
B4: Total Properties Listed | C4: =COUNTA('Property Lookup'!B4:B500) -> 144 | F4: Total Monthly Rent (all bookings) | G4: =SUM('Revenue Tracker'!Z5:Z1004) -> 0
B5: Occupied Properties | C5: =COUNTIF('Property Lookup'!I4:I500,"OCCUPIED") -> 106 | F5: Total Invoiced | G5: =SUM('Revenue Tracker'!AS5:AS1004) -> 0
B6: Vacant Properties | C6: =COUNTIF('Property Lookup'!I4:I500,"VACANT") -> 7 | F6: Total Collected | G6: =SUM('Revenue Tracker'!AT5:AT1004) -> 0
B7: Own Properties | C7: =COUNTIF('Property Lookup'!H4:H500,"OWN") -> 22 | F7: Total Balance Due | G7: =SUM('Revenue Tracker'!AU5:AU1004) -> 0
B8: Sublet Properties | C8: =COUNTIF('Property Lookup'!H4:H500,"SUB") -> 122 | F8: Total Deposits Held | G8: =SUMPRODUCT(('Revenue Tracker'!AC5:AC1004)-('Revenue Tracker'!AK5:AK1004)) -> 0
B10: GUEST KPIs | F10: CLEANING & ANCILLARY (CHF)
B11: Total Bookings | C11: =COUNTA('Revenue Tracker'!B5:B1004) -> 0 | F11: Total Cleaning Due | G11: =SUM('Revenue Tracker'!#REF!) -> #REF!
B12: Unique Guests (Profiles) | C12: =COUNTA('Guest Profiles'!B5:B1004) -> 0 | F12: Total Cleaning Paid | G12: =SUM('Revenue Tracker'!#REF!) -> #REF!
B13: Business Stays | C13: =COUNTIF('Revenue Tracker'!X5:X1004,"Business") -> 0 | F13: Total City Tax | G13: =SUM('Revenue Tracker'!AQ5:AQ1004) -> 0
B14: Leisure Stays | C14: =COUNTIF('Revenue Tracker'!X5:X1004,"Leisure") -> 0 | F14: Total Commission | G14: =SUM('Revenue Tracker'!AR5:AR1004) -> 0
B17: DATABASE SCHEMA — KEY RELATIONSHIPS
B18: Primary Key (PK) | C18: GUEST ID | E18: Unique identifier for each guest in Guest Profiles sheet
B19: Foreign Key (FK-1) | C19: GUEST ID | E19: Links Revenue Tracker → Guest Profiles
B20: Foreign Key (FK-2) | C20: PROPERTY ID | E20: Links Revenue Tracker → Property Lookup
B21: Composite Key | C21: GUEST ID + PROPERTY ID | E21: Uniquely identifies each booking in Revenue Tracker
B22: Booking Ref | C22: SR-YYYY-NNNN | E22: Sequential booking reference tied to a Property ID
B23: Client Code | C23: SG-YYYY-NNNN | E23: SINHA'S internal client code per guest

Sheet Guest Profiles
A1: SINHA'S GmbH — Guest / Client Profile Database
A2: Primary Key: GUEST ID | Neugutstrasse 16, 8304 Wallisellen, Zürich | Confidential
A3: GUEST IDENTIFICATION (PK: Guest ID) | I3: CONTACT DETAILS | P3: ADDRESS — SWITZERLAND | V3: ORIGIN — INDIA / HOME COUNTRY | AB3: COMPANY / EMPLOYER | AH3: INTERNAL / ADMIN
A4: S.No. | B4: Guest ID (PK) | C4: SINHA'S Client Code | D4: Title (Mr/Mrs/Ms/Dr/Prof) | E4: First Name | F4: Last Name / Family Name | G4: Full Name (as per Passport/ID) | H4: Date of Birth (DD.MM.YYYY) | I4: Email ID (Primary) | J4: Email ID (Secondary) | K4: Mobile Number (with Country Code) | L4: WhatsApp Number (with Country Code) | M4: Landline / Office Phone | N4: Preferred Language | O4: Preferred Contact Method | P4: Street & House No. (CH) | Q4: PLZ (Postcode) | R4: City / Ort (CH) | S4: Canton | T4: Country of Residence | U4: Permit Type (L/B/C/G/Other) | V4: Nationality / Citizenship | W4: Passport / ID Number | X4: Place of Origin in India (City) | Y4: State / Region (India) | Z4: Home Address (India / Abroad) | AA4: PIN Code / Postal Code (Home) | AB4: Company / Employer Name | AC4: Designation / Job Title | AD4: Company Address (Switzerland) | AE4: Booking Channel / Partner | AF4: Travel Purpose (Business/Leisure) | AG4: Guest Type (Corp/ Family/ Student/ Intern) | AH4: Guest Type (VIP/ Non-VIP) | AI4: Tier (Diamond/ Gold/ Standard/ Risk) | AJ4: Remarks / Special Notes | AK4: Date Added (DD.MM.YYYY)
A5: =ROW()-4 -> 1
A6: =ROW()-4 -> 2
A7: =ROW()-4 -> 3
A8: =ROW()-4 -> 4
A9: =ROW()-4 -> 5
A10: =ROW()-4 -> 6
A11: =ROW()-4 -> 7
A12: =ROW()-4 -> 8
A13: =ROW()-4 -> 9
A14: =ROW()-4 -> 10
A15: =ROW()-4 -> 11
A16: =ROW()-4 -> 12
... A204: =ROW()-4 -> 200

Sheet Property Lookup
A1: SINHA'S GmbH — Property Master Lookup (FK Reference)
A2: Source: Property_Details_V4 | Property ID is the Foreign Key linking Guest Profiles ↔ Revenue Tracker
A3: S.No. | B3: Property ID (FK) | C3: Full Address | D3: City | E3: PLZ | F3: Rooms | G3: SQM | H3: Own/Sublet | I3: Status | J3: OTA/NON-OTA | K3: Property Type | L3: Canton
A4: 1 | B4: AF10-4L-1.5-APA-SUB-8050-ZH-ZH-CH | C4: Affolternstrasse 10, 8050 Zürich | D4: Zürich | E4: 8050 | F4: 1.5 | G4: 40 | H4: SUB | I4: VACANT
A5: 2 | B5: AL26A-2L-1.5-APA-SUB-8304-WS-ZH-CH | C5: Alte Winterthurerstrasse 26A, 8304 Wallisellen | D5: Wallisellen | E5: 8304 | F5: 1.5 | G5: 35 | H5: SUB | I5: OCCUPIED
A6: 3 | B6: AL26A-4L-1.5-APA-SUB-8304-WS-ZH-CH | C6: Alte Winterthurerstrasse 26A, 8304 Wallisellen | D6: Wallisellen | E6: 8304 | F6: 1.5 | G6: 45 | H6: SUB | I6: OCCUPIED
A7: 4 | B7: AL2-3L-2.5-APA-SUB-8953-DK-ZH-CH | C7: Altbergstrasse 2, 8953 Dietikon | D7: Dietikon | E7: 8953 | F7: 2.5 | G7: 50 | H7: SUB | I7: OCCUPIED
A8: 5 | B8: AL45-1L-3.5-APA-SUB-8134-AW-ZH-CH | C8: Albisstrasse 45, 8134 Adliswil | D8: Adliswil | E8: 8134 | F8: 3.5 | G8: 65 | H8: SUB | I8: OCCUPIED
A9: 6 | B9: AL55-4L-2.5-APA-SUB-8134-AW-ZH-CH | C9: Albisstrasse 55, 8134 Adliswil | D9: Adliswil | E9: 8134 | F9: 2.5 | G9: 50 | H9: SUB | I9: OCCUPIED
A10: 7 | B10: AP21-3L-2.5-APA-SUB-8051-ZH-ZH-CH | C10: Aprikosenstrasse 21, 8051 Zürich | D10: Zürich | E10: 8051 | F10: 2.5 | G10: 60 | H10: SUB | I10: OCCUPIED
A11: 8 | B11: AU2-1L-2.5-APA-OWN-8153-RL-ZH-CH | C11: Ausserdorfstrasse 2, 8153 Rümlang | D11: Rümlang | E11: 8153 | F11: 2.5 | G11: 60 | H11: OWN | I11: OCCUPIED
A12: 9 | B12: AU41-1L-3.5-APA-SUB-8045-ZH-ZH-CH | C12: Austrasse -S7 41, 8045 Zürich | D12: Zürich | E12: 8045 | F12: 3.5 | G12: 80 | H12: SUB | I12: OCCUPIED
A13: 10 | B13: AU41-3L-3.5-APA-SUB-8045-ZH-ZH-CH | C13: Austrasse-S5 41, 8045 Zürich | D13: Zürich | E13: 8045 | F13: 3.5 | G13: 80 | H13: SUB | I13: OCCUPIED
A14: 11 | B14: AU41-4L-3.5-APA-SUB-8045-ZH-ZH-CH | C14: Austrasse-S6 41, 8045 Zürich | D14: Zürich | E14: 8045 | F14: 3.5 | G14: 80 | H14: SUB | I14: OCCUPIED
A15: 12 | B15: AU41-GL-3.5-APA-SUB-8045-ZH-ZH-CH | C15: Austrasse-S4 41, 8045 Zürich | D15: Zürich | E15: 8045 | F15: 3.5 | G15: 80 | H15: SUB | I15: OCCUPIED
... A19: 16 | B19: DE3-2L-3.5-APA-SUB-3073-GU-BE-CH | C19: Dennigkofenweg 3, 3073 Gümligen/ Bern | D19: Gümligen/ Bern | E19: 3073 | F19: 3.5 | G19: 1250 | H19: SUB | I19: SURRENDERED
A20: 17 | B20: DE3-GL-3.5-APA-SUB-3073-GU-BE-CH | C20: Dennigkofenweg 3, 3073 Gümligen/ Bern | D20: Gümligen/ Bern | E20: 3073 | F20: 3.5 | H20: SUB | I20: SURRENDERED
A21: 18 | B21: FR5A-2L-4.5-APA-SUB-8304-WS-ZH-CH | C21: Friedenstrasse 5a, 8304 Wallisellen | D21: Wallisellen | E21: 8304 | F21: 4.5 | G21: 80 | H21: SUB | I21: OCCUPIED
A22: 19 | B22: GR11-3L-4.5-APA-SUB-8304-WS-ZH-CH | C22: Grabenstrasse 11, 8304 Wallisellen | D22: Wallisellen | E22: 8304 | F22: 4.5 | G22: 95 | H22: SUB | I22: OCCUPIED
A23: 20 | B23: GR45A-1L-2.5-APA-SUB-4052-BS-BS-CH | C23: Grosspeterstrasse 45a, 4052 Basel | D23: Basel | E23: 4052 | F23: 2.5 | G23: 60 | H23: SUB | I23: OCCUPIED
A24: 21 | B24: HI60-1L-3.5-APA-SUB-8051-ZH-ZH-CH | C24: Hirzenbachstrasse 60, 8051 Zürich | D24: Zürich | E24: 8051 | F24: 3.5 | G24: 70 | H24: SUB | I24: OCCUPIED
A25: 22 | B25: HI86-GL-2.5-APA-SUB-8051-ZH-ZH-CH | C25: Hirzenbachstrasse 86, 8051 Zürich | D25: Zürich | E25: 8051 | F25: 2.5 | H25: SUB | I25: SURRENDERED
A26: 23 | B26: HO15-4L-3.5-APA-SUB-8045-ZH-ZH-CH | C26: Hopfenstrasse -S3 15, 8045 Zürich | D26: Zürich | E26: 8045 | F26: 3.5 | G26: 80 | H26: SUB | I26: OCCUPIED
A27: 24 | B27: LE16-3L-3.5-APA-SUB-8600-DD-ZH-CH | C27: Leepüntstrasse 16, 8600 Dübendorf | D27: Dübendorf | E27: 8600 | F27: 3.5 | G27: 97.1 | H27: SUB | I27: OCCUPIED
A28: 25 | B28: LE16-2L-1-APA-SUB-8600-DD-ZH-CH | C28: Leepüntstrasse 16, 8600 Dübendorf | D28: Dübendorf | E28: 8600 | F28: 1 | G28: 36 | H28: SUB | I28: OCCUPIED
A29: 26 | B29: LE18-1L-2.5-APA-SUB-8600-DD-ZH-CH | C29: Leepüntstrasse 18, 8600 Dübendorf | D29: Dübendorf | E29: 8600 | F29: 2.5 | G29: 53.7 | H29: SUB | I29: OCCUPIED
A30: 27 | B30: LE18-2L-2.5-APA-SUB-8600-DD-ZH-CH | C30: Leepüntstrasse 18, 8600 Dübendorf | D30: Dübendorf | E30: 8600 | F30: 2.5 | G30: 53.7 | H30: SUB | I30: OCCUPIED
A31: 28 | B31: LE18-3L-2.5-APA-SUB-8600-DD-ZH-CH-A | C31: Leepüntstrasse 18, 8600 Dübendorf | D31: Dübendorf | E31: 8600 | F31: 2.5 | G31: 53.7 | H31: SUB | I31: OCCUPIED
A32: 29 | B32: LE18-3L-2.5-APA-SUB-8600-DD-ZH-CH-B | C32: Leepüntstrasse 18, 8600 Dübendorf | D32: Dübendorf | E32: 8600 | F32: 2.5 | H32: SUB | I32: OCCUPIED
A33: 30 | B33: LE20-1L-2.5-APA-SUB-8600-DD-ZH-CH | C33: Leepüntstrasse 20, 8600 Dübendorf | D33: Dübendorf | E33: 8600 | F33: 2.5 | G33: 53.7 | H33: SUB | I33: OCCUPIED
A34: 31 | B34: LE20-2L-2.5-APA-SUB-8600-DD-ZH-CH | C34: Leepüntstrasse 20, 8600 Dübendorf | D34: Dübendorf | E34: 8600 | F34: 2.5 | G34: 53.7 | H34: SUB | I34: OCCUPIED
A35: 32 | B35: LI8-GL-1-APA-SUB-8304-WS-ZH-CH | C35: Lindenstrasse 8, 8304 Wallisellen | D35: Wallisellen | E35: 8304 | F35: 1 | G35: 16 | H35: SUB | I35: OCCUPIED
A36: 33 | B36: ME14-3L-2.5-APA-SUB-8304-WS-ZH-CH | C36: Melchrütistrasse 14, 8304 Wallisellen | D36: Wallisellen | E36: 8304 | F36: 2.5 | G36: 70 | H36: SUB | I36: OCCUPIED
A37: 34 | B37: NE75-2L-3.5-APA-SUB-8304-WS-ZH-CH | C37: Neue Winterthurerstrasse 75, 8304 Wallisellen | D37: Wallisellen | E37: 8304 | F37: 3.5 | G37: 70 | H37: SUB | I37: OCCUPIED
A38: 35 | B38: RI143-1L-2.5-APA-SUB-4058-BS-BS-CH | C38: Riehenring 143, 4058 Basel | D38: Basel | E38: 4058 | F38: 2.5 | G38: 55 | H38: SUB | I38: OCCUPIED
A39: 36 | B39: RI143-5L-2.5-APA-SUB-4058-BS-BS-CH | C39: Riehenring 143, 4058 Basel | D39: Basel | E39: 4058 | F39: 2.5 | G39: 55 | H39: SUB | I39: OCCUPIED
A40: 37 | B40: RI167-4L-3.5-APA-SUB-4058-BS-BS-CH | C40: Riehenstrasse 167, 4058 Basel | D40: Basel | E40: 4058 | F40: 3.5 | G40: 60 | H40: SUB | I40: OCCUPIED
A41: 38 | B41: RI16-2L-3.5-APA-SUB-6300-ZG-ZG-CH | C41: Riedmatweg 16, 6300 Zug | D41: Zug | E41: 6300 | F41: 3.5 | H41: SUB | I41: SURRENDERED
A42: 39 | B42: SC1A-2L-2.5-APA-SUB-8304-WS-ZH-CH | C42: Schutzenstrasse 1a, 8304 Wallisellen | D42: Wallisellen | E42: 8304 | F42: 2.5 | G42: 68 | H42: SUB | I42: OCCUPIED
A43: 40 | B43: SE64-2L-2.5-APA-OWN-8052-ZH-ZH-CH | C43: Seebacherstrasse 64, 8052 Zürich | D43: Zürich | E43: 8052 | F43: 2.5 | G43: 60 | H43: OWN | I43: OCCUPIED
...

Sheet Revenue Tracker
A1: SINHA'S GmbH — Revenue Tracker
A2: Composite Key: GUEST ID (FK → Guest Profiles) + PROPERTY ID (FK → Property Lookup) | All amounts in CHF
A3: KEYS (Guest ID + Property ID) | E3: GUEST SUMMARY | J3: PROPERTY SUMMARY | Q3: STAY DETAILS | Y3: REVENUE & FINANCIALS (CHF) | AV3: STATUS & NOTES
A4: S.No. | B4: Booking Ref No. | C4: Guest ID (FK → Guest Profiles) | D4: Property ID (FK → Property Lookup) | E4: Guest Full Name | F4: Nationality | G4: Company / Employer | H4: Mobile | I4: Email | J4: Property Address | K4: City | L4: Rooms | M4: SQM | N4: Own / Sublet | O4: Property Type | P4: Booking Channel | Q4: Move Within SINHA'S | R4: Check-in Date | S4: Check-out Date | T4: Guest Nights | U4: No. of Guests | V4: Children (under 16) | W4: Stay Type (Short/Long) | X4: Purpose (Business/ Leisure) | Y4: Currency | Z4: Monthly Rent (CHF) | AA4: Pro-Rate Daily Rate (CHF) | AB4: Total Rent (CHF) | AC4: Deposit (CHF) | AD4: Deposit Paid Date | AE4: Cleaning Paid (CHF) | AF4: Cleaning Due (CHF) | AG4: Additional Cleaning( if applicable) | AH4: Reimbursement | AI4: Pet Fee | AJ4: Net Deposit | AK4: Deposit Returned (CHF) | AL4: Deposit Return Date | AM4: Deposit Refund Source (Own/Sublet Bank) | AN4: SINHA'S Internal Deposit Adjustments | AO4: Guest IBAN / Account Nr (for Refund) | AP4: Notice Period Rent / Deposit Adjustments | AQ4: City Tax (CHF) | AR4: Commission (CHF) | AS4: Total Invoice (CHF) | AT4: Total Paid (CHF) | AU4: Balance Due (CHF) | AV4: Payment Method | AW4: Payment Status | AX4: Booking Status | AY4: Remarks | AZ4: Last Updated
A5: =ROW()-4 -> 1 | T5: =IF(AND(R5<>"",S5<>""),S5-R5,"") | Y5: CHF | AA5: =IF(Z5<>"",ROUND(Z5/30,2),"") | AB5: =IF(AND(Z5<>"",T5<>""),ROUND(Z5/30*T5,2),"") | AS5: =IF(AB5<>"",AB5+IF(#REF!<>"",#REF!,0)+IF(AQ5<>"",AQ5,0)+IF(AR5<>"",AR5,0),"") | AU5: =IF(AS5<>"",AS5-IF(AT5<>"",AT5,0),"")
A6: =ROW()-4 -> 2 | T6: =IF(AND(R6<>"",S6<>""),S6-R6,"") | Y6: CHF | AA6: =IF(Z6<>"",ROUND(Z6/30,2),"") | AB6: =IF(AND(Z6<>"",T6<>""),ROUND(Z6/30*T6,2),"") | AS6: =IF(AB6<>"",AB6+IF(#REF!<>"",#REF!,0)+IF(AQ6<>"",AQ6,0)+IF(AR6<>"",AR6,0),"") | AU6: =IF(AS6<>"",AS6-IF(AT6<>"",AT6,0),"")
A7: =ROW()-4 -> 3 | T7: =IF(AND(R7<>"",S7<>""),S7-R7,"") | Y7: CHF | AA7: =IF(Z7<>"",ROUND(Z7/30,2),"") | AB7: =IF(AND(Z7<>"",T7<>""),ROUND(Z7/30*T7,2),"") | AS7: =IF(AB7<>"",AB7+IF(#REF!<>"",#REF!,0)+IF(AQ7<>"",AQ7,0)+IF(AR7<>"",AR7,0),"") | AU7: =IF(AS7<>"",AS7-IF(AT7<>"",AT7,0),"")
A8: =ROW()-4 -> 4 | T8: =IF(AND(R8<>"",S8<>""),S8-R8,"") | Y8: CHF | AA8: =IF(Z8<>"",ROUND(Z8/30,2),"") | AB8: =IF(AND(Z8<>"",T8<>""),ROUND(Z8/30*T8,2),"") | AS8: =IF(AB8<>"",AB8+IF(#REF!<>"",#REF!,0)+IF(AQ8<>"",AQ8,0)+IF(AR8<>"",AR8,0),"") | AU8: =IF(AS8<>"",AS8-IF(AT8<>"",AT8,0),"")
A9: =ROW()-4 -> 5 | T9: =IF(AND(R9<>"",S9<>""),S9-R9,"") | Y9: CHF | AA9: =IF(Z9<>"",ROUND(Z9/30,2),"") | AB9: =IF(AND(Z9<>"",T9<>""),ROUND(Z9/30*T9,2),"") | AS9: =IF(AB9<>"",AB9+IF(#REF!<>"",#REF!,0)+IF(AQ9<>"",AQ9,0)+IF(AR9<>"",AR9,0),"") | AU9: =IF(AS9<>"",AS9-IF(AT9<>"",AT9,0),"")
A10: =ROW()-4 -> 6 | T10: =IF(AND(R10<>"",S10<>""),S10-R10,"") | Y10: CHF | AA10: =IF(Z10<>"",ROUND(Z10/30,2),"") | AB10: =IF(AND(Z10<>"",T10<>""),ROUND(Z10/30*T10,2),"") | AS10: =IF(AB10<>"",AB10+IF(#REF!<>"",#REF!,0)+IF(AQ10<>"",AQ10,0)+IF(AR10<>"",AR10,0),"") | AU10: =IF(AS10<>"",AS10-IF(AT10<>"",AT10,0),"")
A11: =ROW()-4 -> 7 | T11: =IF(AND(R11<>"",S11<>""),S11-R11,"") | Y11: CHF | AA11: =IF(Z11<>"",ROUND(Z11/30,2),"") | AB11: =IF(AND(Z11<>"",T11<>""),ROUND(Z11/30*T11,2),"") | AS11: =IF(AB11<>"",AB11+IF(#REF!<>"",#REF!,0)+IF(AQ11<>"",AQ11,0)+IF(AR11<>"",AR11,0),"") | AU11: =IF(AS11<>"",AS11-IF(AT11<>"",AT11,0),"")
A12: =ROW()-4 -> 8 | T12: =IF(AND(R12<>"",S12<>""),S12-R12,"") | Y12: CHF | AA12: =IF(Z12<>"",ROUND(Z12/30,2),"") | AB12: =IF(AND(Z12<>"",T12<>""),ROUND(Z12/30*T12,2),"") | AS12: =IF(AB12<>"",AB12+IF(#REF!<>"",#REF!,0)+IF(AQ12<>"",AQ12,0)+IF(AR12<>"",AR12,0),"") | AU12: =IF(AS12<>"",AS12-IF(AT12<>"",AT12,0),"")
A13: =ROW()-4 -> 9 | T13: =IF(AND(R13<>"",S13<>""),S13-R13,"") | Y13: CHF | AA13: =IF(Z13<>"",ROUND(Z13/30,2),"") | AB13: =IF(AND(Z13<>"",T13<>""),ROUND(Z13/30*T13,2),"") | AS13: =IF(AB13<>"",AB13+IF(#REF!<>"",#REF!,0)+IF(AQ13<>"",AQ13,0)+IF(AR13<>"",AR13,0),"") | AU13: =IF(AS13<>"",AS13-IF(AT13<>"",AT13,0),"")
A14: =ROW()-4 -> 10 | T14: =IF(AND(R14<>"",S14<>""),S14-R14,"") | Y14: CHF | AA14: =IF(Z14<>"",ROUND(Z14/30,2),"") | AB14: =IF(AND(Z14<>"",T14<>""),ROUND(Z14/30*T14,2),"") | AS14: =IF(AB14<>"",AB14+IF(#REF!<>"",#REF!,0)+IF(AQ14<>"",AQ14,0)+IF(AR14<>"",AR14,0),"") | AU14: =IF(AS14<>"",AS14-IF(AT14<>"",AT14,0),"")
A15: =ROW()-4 -> 11 | T15: =IF(AND(R15<>"",S15<>""),S15-R15,"") | Y15: CHF | AA15: =IF(Z15<>"",ROUND(Z15/30,2),"") | AB15: =IF(AND(Z15<>"",T15<>""),ROUND(Z15/30*T15,2),"") | AS15: =IF(AB15<>"",AB15+IF(#REF!<>"",#REF!,0)+IF(AQ15<>"",AQ15,0)+IF(AR15<>"",AR15,0),"") | AU15: =IF(AS15<>"",AS15-IF(AT15<>"",AT15,0),"")
A16: =ROW()-4 -> 12 | T16: =IF(AND(R16<>"",S16<>""),S16-R16,"") | Y16: CHF | AA16: =IF(Z16<>"",ROUND(Z16/30,2),"") | AB16: =IF(AND(Z16<>"",T16<>""),ROUND(Z16/30*T16,2),"") | AS16: =IF(AB16<>"",AB16+IF(#REF!<>"",#REF!,0)+IF(AQ16<>"",AQ16,0)+IF(AR16<>"",AR16,0),"") | AU16: =IF(AS16<>"",AS16-IF(AT16<>"",AT16,0),"")
... A204: =ROW()-4 -> 200 | T204: =IF(AND(R204<>"",S204<>""),S204-R204,"") | Y204: CHF | AA204: =IF(Z204<>"",ROUND(Z204/30,2),"") | AB204: =IF(AND(Z204<>"",T204<>""),ROUND(Z204/30*T204,2),"") | AS204: =IF(AB204<>"",AB204+IF(#REF!<>"",#REF!,0)+IF(AQ204<>"",AQ204,0)+IF(AR204<>"",AR204,0),"") | AU204: =IF(AS204<>"",AS204-IF(AT204<>"",AT204,0),"")

Sheet Data Dictionary
A1: SINHA'S GmbH — Database Schema — Field Definitions & Key Relationships
A2: Sheet | B2: Field Name | C2: Column | D2: Key Type | E2: Data Type | F2: Description | G2: Example / Format
A3: Guest Profiles | B3: Guest ID | C3: B | D3: PK | E3: Text | F3: System-generated unique guest identifier | G3: 23696522
A4: Guest Profiles | B4: SINHA'S Client Code | C4: C | D4: — | E4: Text | F4: Internal client code: SG-YYYY-NNNN | G4: SG-2026-0001
A5: Guest Profiles | B5: Full Name | C5: G | D5: — | E5: Text | F5: Legal name as per Passport/ID | G5: Mr. Rajeev Sinha
A6: Guest Profiles | B6: Email (Primary) | C6: I | D6: — | E6: Text | F6: Primary email for correspondence | G6: guest@company.com
A7: Guest Profiles | B7: Mobile Number | C7: K | D7: — | E7: Text | F7: Mobile with international code | G7: +91 98765 43210
A8: Guest Profiles | B8: WhatsApp Number | C8: L | D8: — | E8: Text | F8: WhatsApp-registered number | G8: +41 79 123 45 67
A9: Guest Profiles | B9: Place of Origin (India) | C9: X | D9: — | E9: Text | F9: Home city in India | G9: Bengaluru
A10: Guest Profiles | B10: Company / Employer | C10: AB | D10: — | E10: Text | F10: Corporate client name | G10: Tech Mahindra Limited
A12: Property Lookup | B12: Property ID | C12: B | D12: PK/FK | E12: Text | F12: Smart Property ID from Property Master | G12: AU41-1L-3.5-APA-SUB-8045-ZH-ZH-CH
A13: Property Lookup | B13: Full Address | C13: C | D13: — | E13: Text | F13: Complete property address | G13: Austrasse 41, 8045 Zürich
A14: Property Lookup | B14: Own/Sublet | C14: H | D14: — | E14: Text | F14: Ownership status | G14: OWN / SUB
... A26: Revenue Tracker | B26: Balance Due (CHF) | C26: AP | D26: — | E26: Formula | F26: Total Invoice minus Total Paid | G26: 0.00
